{
    "registryname": "electronic_assembly_machine_mk2",
    "localizedname": "at.electronic_assembly_machine_mk2.name",
    "color" : "383736",
    "requires-blueprint": true,
    "parts": [
        {
            "x": -1,
            "y": 0,
            "z": 0,
            "elements": [
                "modularmachinery:blockcircuitry"
            ]
        },
        {
            "x": 0,
            "y": 0,
            "z": 0,
            "elements": [
                "modularmachinery:blockcontroller"
            ]
        },
        {
            "x": 1,
            "y": 2,
            "z": 1,
            "elements": [
                "modularmachinery:blockcircuitry"
            ]
        },
        {
            "x": 1,
            "y": 0,
            "z": 0,
            "elements": [
                "modularmachinery:blockcircuitry"
            ]
        },
        {
            "x": 1,
            "y": -1,
            "z": 0,
            "elements": [
                "modularmachinery:blockcircuitry"
            ]
        },
        {
            "x": 0,
            "y": -1,
            "z": 0,
            "elements": [
                "modularmachinery:blockenergyinputhatch"
            ]
        },
        {
            "x": -1,
            "y": 1,
            "z": 0,
            "elements": [
                "modularmachinery:blockcircuitry"
            ]
        },
        {
            "x": -1,
            "y": -1,
            "z": 0,
            "elements": [
                "modularmachinery:blockcircuitry"
            ]
        },
        {
            "x": 0,
            "y": 1,
            "z": 0,
            "elements": [
                "modularmachinery:blockoutputbus"
            ]
        },
        {
            "x": 1,
            "y": 1,
            "z": 0,
            "elements": [
                "modularmachinery:blockcircuitry"
            ]
        },
        {
            "x": -1,
            "y": -1,
            "z": 6,
            "elements": [
                "modularmachinery:blockcircuitry"
            ]
        },
        {
            "x": 0,
            "y": -1,
            "z": 6,
            "elements": [
                "thermalfoundation:storage_alloy@2"
            ]
        },
        {
            "x": 1,
            "y": -1,
            "z": 6,
            "elements": [
                "modularmachinery:blockcircuitry"
            ]
        },
        {
            "x": -1,
            "y": 0,
            "z": 6,
            "elements": [
                "modularmachinery:blockcircuitry"
            ]
        },
        {
            "x": -1,
            "y": -2,
            "z": 5,
            "elements": [
                "modularmachinery:blockcircuitry"
            ]
        },
        {
            "x": 0,
            "y": 0,
            "z": 6,
            "elements": [
                "thermalfoundation:storage_alloy@2"
            ]
        },
        {
            "x": 0,
            "y": -2,
            "z": 5,
            "elements": [
                "thermalfoundation:storage_alloy@2"
            ]
        },
        {
            "x": 1,
            "y": 0,
            "z": 6,
            "elements": [
                "modularmachinery:blockcircuitry"
            ]
        },
        {
            "x": 1,
            "y": -2,
            "z": 5,
            "elements": [
                "modularmachinery:blockcircuitry"
            ]
        },
        {
            "x": -4,
            "y": -1,
            "z": 5,
            "elements": [
                "modularmachinery:blockcasing"
            ]
        },
        {
            "x": -3,
            "y": -1,
            "z": 5,
            "elements": [
                "modularmachinery:blockcasing"
            ]
        },
        {
            "x": -2,
            "y": -1,
            "z": 5,
            "elements": [
                "thermalfoundation:storage_alloy@2"
            ]
        },
        {
            "x": -1,
            "y": 1,
            "z": 6,
            "elements": [
                "modularmachinery:blockcircuitry"
            ]
        },
        {
            "x": -1,
            "y": -1,
            "z": 5,
            "elements": [
                "nuclearcraft:solid_fission_sink@3"
            ]
        },
        {
            "x": 0,
            "y": 1,
            "z": 6,
            "elements": [
                "thermalfoundation:storage_alloy@2"
            ]
        },
        {
            "x": 0,
            "y": -1,
            "z": 5,
            "elements": [
                "nuclearcraft:solid_fission_sink@7"
            ]
        },
        {
            "x": 1,
            "y": 1,
            "z": 6,
            "elements": [
                "modularmachinery:blockcircuitry"
            ]
        },
        {
            "x": 1,
            "y": -1,
            "z": 5,
            "elements": [
                "nuclearcraft:solid_fission_sink@3"
            ]
        },
        {
            "x": 2,
            "y": -1,
            "z": 5,
            "elements": [
                "thermalfoundation:storage_alloy@2"
            ]
        },
        {
            "x": 3,
            "y": -1,
            "z": 5,
            "elements": [
                "modularmachinery:blockcasing"
            ]
        },
        {
            "x": 4,
            "y": -1,
            "z": 5,
            "elements": [
                "modularmachinery:blockcasing"
            ]
        },
        {
            "x": -4,
            "y": 0,
            "z": 5,
            "elements": [
                "modularmachinery:blockcasing"
            ]
        },
        {
            "x": -4,
            "y": -2,
            "z": 4,
            "elements": [
                "modularmachinery:blockcasing"
            ]
        },
        {
            "x": -3,
            "y": 0,
            "z": 5,
            "elements": [
                "modularmachinery:blockcasing"
            ]
        },
        {
            "x": -3,
            "y": -2,
            "z": 4,
            "elements": [
                "modularmachinery:blockcasing"
            ]
        },
        {
            "x": -2,
            "y": 0,
            "z": 5,
            "elements": [
                "thermalfoundation:storage_alloy@2"
            ]
        },
        {
            "x": -2,
            "y": -2,
            "z": 4,
            "elements": [
                "thermalfoundation:storage_alloy@2"
            ]
        },
        {
            "x": -1,
            "y": 0,
            "z": 5,
            "elements": [
                "nuclearcraft:solid_fission_sink@7"
            ]
        },
        {
            "x": -1,
            "y": -2,
            "z": 4,
            "elements": [
                "modularmachinery:blockcircuitry"
            ]
        },
        {
            "x": 0,
            "y": 0,
            "z": 5,
            "elements": [
                "refraction:electric_laser@2"
            ]
        },
        {
            "x": 0,
            "y": -2,
            "z": 4,
            "elements": [
                "thermalfoundation:storage_alloy@2"
            ]
        },
        {
            "x": 1,
            "y": 0,
            "z": 5,
            "elements": [
                "nuclearcraft:solid_fission_sink@7"
            ]
        },
        {
            "x": 1,
            "y": -2,
            "z": 4,
            "elements": [
                "modularmachinery:blockcircuitry"
            ]
        },
        {
            "x": 2,
            "y": 0,
            "z": 5,
            "elements": [
                "thermalfoundation:storage_alloy@2"
            ]
        },
        {
            "x": 2,
            "y": -2,
            "z": 4,
            "elements": [
                "thermalfoundation:storage_alloy@2"
            ]
        },
        {
            "x": 3,
            "y": 0,
            "z": 5,
            "elements": [
                "modularmachinery:blockcasing"
            ]
        },
        {
            "x": 3,
            "y": -2,
            "z": 4,
            "elements": [
                "modularmachinery:blockcasing"
            ]
        },
        {
            "x": 4,
            "y": 0,
            "z": 5,
            "elements": [
                "modularmachinery:blockcasing"
            ]
        },
        {
            "x": 4,
            "y": -2,
            "z": 4,
            "elements": [
                "modularmachinery:blockcasing"
            ]
        },
        {
            "x": -5,
            "y": -1,
            "z": 4,
            "elements": [
                "modularmachinery:blockcasing"
            ]
        },
        {
            "x": -4,
            "y": 1,
            "z": 5,
            "elements": [
                "modularmachinery:blockcasing"
            ]
        },
        {
            "x": -4,
            "y": -1,
            "z": 4,
            "elements": [
                "nuclearcraft:solid_fission_sink@3"
            ]
        },
        {
            "x": -3,
            "y": 1,
            "z": 5,
            "elements": [
                "modularmachinery:blockcasing"
            ]
        },
        {
            "x": -2,
            "y": 1,
            "z": 5,
            "elements": [
                "thermalfoundation:storage_alloy@2"
            ]
        },
        {
            "x": -1,
            "y": 1,
            "z": 5,
            "elements": [
                "nuclearcraft:solid_fission_sink@3"
            ]
        },
        {
            "x": 0,
            "y": 1,
            "z": 5,
            "elements": [
                "nuclearcraft:solid_fission_sink@7"
            ]
        },
        {
            "x": 1,
            "y": 1,
            "z": 5,
            "elements": [
                "nuclearcraft:solid_fission_sink@3"
            ]
        },
        {
            "x": 2,
            "y": 1,
            "z": 5,
            "elements": [
                "thermalfoundation:storage_alloy@2"
            ]
        },
        {
            "x": 3,
            "y": 1,
            "z": 5,
            "elements": [
                "modularmachinery:blockcasing"
            ]
        },
        {
            "x": 4,
            "y": 1,
            "z": 5,
            "elements": [
                "modularmachinery:blockcasing"
            ]
        },
        {
            "x": 4,
            "y": -1,
            "z": 4,
            "elements": [
                "nuclearcraft:solid_fission_sink@3"
            ]
        },
        {
            "x": 5,
            "y": -1,
            "z": 4,
            "elements": [
                "modularmachinery:blockcasing"
            ]
        },
        {
            "x": -5,
            "y": 0,
            "z": 4,
            "elements": [
                "modularmachinery:blockcasing"
            ]
        },
        {
            "x": -4,
            "y": 0,
            "z": 4,
            "elements": [
                "nuclearcraft:solid_fission_sink@7"
            ]
        },
        {
            "x": -4,
            "y": -2,
            "z": 3,
            "elements": [
                "modularmachinery:blockcasing"
            ]
        },
        {
            "x": -3,
            "y": -2,
            "z": 3,
            "elements": [
                "modularmachinery:blockcasing"
            ]
        },
        {
            "x": -1,
            "y": 2,
            "z": 5,
            "elements": [
                "modularmachinery:blockcircuitry"
            ]
        },
        {
            "x": -2,
            "y": -2,
            "z": 3,
            "elements": [
                "thermalfoundation:storage_alloy@2"
            ]
        },
        {
            "x": 0,
            "y": 2,
            "z": 5,
            "elements": [
                "thermalfoundation:storage_alloy@2"
            ]
        },
        {
            "x": -1,
            "y": -2,
            "z": 3,
            "elements": [
                "modularmachinery:blockcircuitry"
            ]
        },
        {
            "x": 0,
            "y": 0,
            "z": 4,
            "elements": [
                "appliedenergistics2:molecular_assembler@0"
            ]
        },
        {
            "x": 1,
            "y": 2,
            "z": 5,
            "elements": [
                "modularmachinery:blockcircuitry"
            ]
        },
        {
            "x": 0,
            "y": -2,
            "z": 3,
            "elements": [
                "thermalfoundation:storage_alloy@2"
            ]
        },
        {
            "x": 1,
            "y": -2,
            "z": 3,
            "elements": [
                "modularmachinery:blockcircuitry"
            ]
        },
        {
            "x": 2,
            "y": -2,
            "z": 3,
            "elements": [
                "thermalfoundation:storage_alloy@2"
            ]
        },
        {
            "x": 3,
            "y": -2,
            "z": 3,
            "elements": [
                "modularmachinery:blockcasing"
            ]
        },
        {
            "x": 4,
            "y": 0,
            "z": 4,
            "elements": [
                "nuclearcraft:solid_fission_sink@7"
            ]
        },
        {
            "x": 4,
            "y": -2,
            "z": 3,
            "elements": [
                "modularmachinery:blockcasing"
            ]
        },
        {
            "x": 5,
            "y": 0,
            "z": 4,
            "elements": [
                "modularmachinery:blockcasing"
            ]
        },
        {
            "x": -5,
            "y": 1,
            "z": 4,
            "elements": [
                "modularmachinery:blockcasing"
            ]
        },
        {
            "x": -5,
            "y": -1,
            "z": 3,
            "elements": [
                "modularmachinery:blockcasing"
            ]
        },
        {
            "x": -4,
            "y": 1,
            "z": 4,
            "elements": [
                "nuclearcraft:solid_fission_sink@3"
            ]
        },
        {
            "x": -4,
            "y": -1,
            "z": 3,
            "elements": [
                "nuclearcraft:solid_fission_sink@7"
            ]
        },
        {
            "x": 4,
            "y": 1,
            "z": 4,
            "elements": [
                "nuclearcraft:solid_fission_sink@3"
            ]
        },
        {
            "x": 4,
            "y": -1,
            "z": 3,
            "elements": [
                "nuclearcraft:solid_fission_sink@7"
            ]
        },
        {
            "x": 5,
            "y": 1,
            "z": 4,
            "elements": [
                "modularmachinery:blockcasing"
            ]
        },
        {
            "x": 5,
            "y": -1,
            "z": 3,
            "elements": [
                "modularmachinery:blockcasing"
            ]
        },
        {
            "x": -5,
            "y": 0,
            "z": 3,
            "elements": [
                "modularmachinery:blockcasing"
            ]
        },
        {
            "x": -4,
            "y": 2,
            "z": 4,
            "elements": [
                "modularmachinery:blockcasing"
            ]
        },
        {
            "x": -4,
            "y": 0,
            "z": 3,
            "elements": [
                "refraction:electric_laser@5"
            ]
        },
        {
            "x": -3,
            "y": 2,
            "z": 4,
            "elements": [
                "modularmachinery:blockcasing"
            ]
        },
        {
            "x": -4,
            "y": -2,
            "z": 2,
            "elements": [
                "modularmachinery:blockcasing"
            ]
        },
        {
            "x": -3,
            "y": 0,
            "z": 3,
            "elements": [
                "appliedenergistics2:molecular_assembler@0"
            ]
        },
        {
            "x": -2,
            "y": 2,
            "z": 4,
            "elements": [
                "thermalfoundation:storage_alloy@2"
            ]
        },
        {
            "x": -3,
            "y": -2,
            "z": 2,
            "elements": [
                "modularmachinery:blockcasing"
            ]
        },
        {
            "x": -2,
            "y": 0,
            "z": 3,
            "elements": [
                "appliedenergistics2:molecular_assembler@0"
            ]
        },
        {
            "x": -1,
            "y": 2,
            "z": 4,
            "elements": [
                "nuclearcraft:solid_fission_sink@3"
            ]
        },
        {
            "x": -2,
            "y": -2,
            "z": 2,
            "elements": [
                "thermalfoundation:storage_alloy@2"
            ]
        },
        {
            "x": -1,
            "y": 0,
            "z": 3,
            "elements": [
                "appliedenergistics2:molecular_assembler@0"
            ]
        },
        {
            "x": 0,
            "y": 2,
            "z": 4,
            "elements": [
                "nuclearcraft:solid_fission_sink@7"
            ]
        },
        {
            "x": -1,
            "y": -2,
            "z": 2,
            "elements": [
                "modularmachinery:blockcircuitry"
            ]
        },
        {
            "x": 0,
            "y": 0,
            "z": 3,
            "elements": [
                "refraction:reflection_chamber@0"
            ]
        },
        {
            "x": 1,
            "y": 2,
            "z": 4,
            "elements": [
                "nuclearcraft:solid_fission_sink@3"
            ]
        },
        {
            "x": 0,
            "y": -2,
            "z": 2,
            "elements": [
                "thermalfoundation:storage_alloy@2"
            ]
        },
        {
            "x": 1,
            "y": 0,
            "z": 3,
            "elements": [
                "appliedenergistics2:molecular_assembler@0"
            ]
        },
        {
            "x": 2,
            "y": 2,
            "z": 4,
            "elements": [
                "thermalfoundation:storage_alloy@2"
            ]
        },
        {
            "x": 1,
            "y": -2,
            "z": 2,
            "elements": [
                "modularmachinery:blockcircuitry"
            ]
        },
        {
            "x": 2,
            "y": 0,
            "z": 3,
            "elements": [
                "appliedenergistics2:molecular_assembler@0"
            ]
        },
        {
            "x": 3,
            "y": 2,
            "z": 4,
            "elements": [
                "modularmachinery:blockcasing"
            ]
        },
        {
            "x": 2,
            "y": -2,
            "z": 2,
            "elements": [
                "thermalfoundation:storage_alloy@2"
            ]
        },
        {
            "x": 3,
            "y": 0,
            "z": 3,
            "elements": [
                "appliedenergistics2:molecular_assembler@0"
            ]
        },
        {
            "x": 4,
            "y": 2,
            "z": 4,
            "elements": [
                "modularmachinery:blockcasing"
            ]
        },
        {
            "x": 3,
            "y": -2,
            "z": 2,
            "elements": [
                "modularmachinery:blockcasing"
            ]
        },
        {
            "x": 4,
            "y": 0,
            "z": 3,
            "elements": [
                "refraction:electric_laser@4"
            ]
        },
        {
            "x": 4,
            "y": -2,
            "z": 2,
            "elements": [
                "modularmachinery:blockcasing"
            ]
        },
        {
            "x": 5,
            "y": 0,
            "z": 3,
            "elements": [
                "modularmachinery:blockcasing"
            ]
        },
        {
            "x": -5,
            "y": 1,
            "z": 3,
            "elements": [
                "modularmachinery:blockcasing"
            ]
        },
        {
            "x": -5,
            "y": -1,
            "z": 2,
            "elements": [
                "modularmachinery:blockcasing"
            ]
        },
        {
            "x": -4,
            "y": 1,
            "z": 3,
            "elements": [
                "nuclearcraft:solid_fission_sink@7"
            ]
        },
        {
            "x": -4,
            "y": -1,
            "z": 2,
            "elements": [
                "nuclearcraft:solid_fission_sink@3"
            ]
        },
        {
            "x": -1,
            "y": 3,
            "z": 4,
            "elements": [
                "modularmachinery:blockcircuitry"
            ]
        },
        {
            "x": 0,
            "y": 3,
            "z": 4,
            "elements": [
                "thermalfoundation:storage_alloy@2"
            ]
        },
        {
            "x": 0,
            "y": 1,
            "z": 3,
            "elements": [
                "appliedenergistics2:molecular_assembler@0"
            ]
        },
        {
            "x": 1,
            "y": 3,
            "z": 4,
            "elements": [
                "modularmachinery:blockcircuitry"
            ]
        },
        {
            "x": 4,
            "y": 1,
            "z": 3,
            "elements": [
                "nuclearcraft:solid_fission_sink@7"
            ]
        },
        {
            "x": 4,
            "y": -1,
            "z": 2,
            "elements": [
                "nuclearcraft:solid_fission_sink@3"
            ]
        },
        {
            "x": 5,
            "y": 1,
            "z": 3,
            "elements": [
                "modularmachinery:blockcasing"
            ]
        },
        {
            "x": 5,
            "y": -1,
            "z": 2,
            "elements": [
                "modularmachinery:blockcasing"
            ]
        },
        {
            "x": -5,
            "y": 0,
            "z": 2,
            "elements": [
                "modularmachinery:blockcasing"
            ]
        },
        {
            "x": -4,
            "y": 2,
            "z": 3,
            "elements": [
                "modularmachinery:blockcasing"
            ]
        },
        {
            "x": -4,
            "y": 0,
            "z": 2,
            "elements": [
                "nuclearcraft:solid_fission_sink@7"
            ]
        },
        {
            "x": -3,
            "y": 2,
            "z": 3,
            "elements": [
                "modularmachinery:blockcasing"
            ]
        },
        {
            "x": -2,
            "y": 2,
            "z": 3,
            "elements": [
                "thermalfoundation:storage_alloy@2"
            ]
        },
        {
            "x": -1,
            "y": 2,
            "z": 3,
            "elements": [
                "nuclearcraft:solid_fission_sink@7"
            ]
        },
        {
            "x": 0,
            "y": 2,
            "z": 3,
            "elements": [
                "refraction:electric_laser@0"
            ]
        },
        {
            "x": -1,
            "y": -2,
            "z": 1,
            "elements": [
                "modularmachinery:blockcircuitry"
            ]
        },
        {
            "x": 0,
            "y": 0,
            "z": 2,
            "elements": [
                "appliedenergistics2:molecular_assembler@0"
            ]
        },
        {
            "x": 1,
            "y": 2,
            "z": 3,
            "elements": [
                "nuclearcraft:solid_fission_sink@7"
            ]
        },
        {
            "x": 0,
            "y": -2,
            "z": 1,
            "elements": [
                "thermalfoundation:storage_alloy@2"
            ]
        },
        {
            "x": 2,
            "y": 2,
            "z": 3,
            "elements": [
                "thermalfoundation:storage_alloy@2"
            ]
        },
        {
            "x": 1,
            "y": -2,
            "z": 1,
            "elements": [
                "modularmachinery:blockcircuitry"
            ]
        },
        {
            "x": 3,
            "y": 2,
            "z": 3,
            "elements": [
                "modularmachinery:blockcasing"
            ]
        },
        {
            "x": 4,
            "y": 2,
            "z": 3,
            "elements": [
                "modularmachinery:blockcasing"
            ]
        },
        {
            "x": 4,
            "y": 0,
            "z": 2,
            "elements": [
                "nuclearcraft:solid_fission_sink@7"
            ]
        },
        {
            "x": 5,
            "y": 0,
            "z": 2,
            "elements": [
                "modularmachinery:blockcasing"
            ]
        },
        {
            "x": -5,
            "y": 1,
            "z": 2,
            "elements": [
                "modularmachinery:blockcasing"
            ]
        },
        {
            "x": -4,
            "y": 1,
            "z": 2,
            "elements": [
                "nuclearcraft:solid_fission_sink@3"
            ]
        },
        {
            "x": -4,
            "y": -1,
            "z": 1,
            "elements": [
                "modularmachinery:blockcasing"
            ]
        },
        {
            "x": -3,
            "y": -1,
            "z": 1,
            "elements": [
                "modularmachinery:blockfluidinputhatch"
            ]
        },
        {
            "x": -1,
            "y": 3,
            "z": 3,
            "elements": [
                "modularmachinery:blockcircuitry"
            ]
        },
        {
            "x": -2,
            "y": -1,
            "z": 1,
            "elements": [
                "thermalfoundation:storage_alloy@2"
            ]
        },
        {
            "x": 0,
            "y": 3,
            "z": 3,
            "elements": [
                "thermalfoundation:storage_alloy@2"
            ]
        },
        {
            "x": -1,
            "y": -1,
            "z": 1,
            "elements": [
                "nuclearcraft:solid_fission_sink@3"
            ]
        },
        {
            "x": 1,
            "y": 3,
            "z": 3,
            "elements": [
                "modularmachinery:blockcircuitry"
            ]
        },
        {
            "x": 0,
            "y": -1,
            "z": 1,
            "elements": [
                "nuclearcraft:solid_fission_sink@7"
            ]
        },
        {
            "x": 1,
            "y": -1,
            "z": 1,
            "elements": [
                "nuclearcraft:solid_fission_sink@3"
            ]
        },
        {
            "x": 2,
            "y": -1,
            "z": 1,
            "elements": [
                "thermalfoundation:storage_alloy@2"
            ]
        },
        {
            "x": 3,
            "y": -1,
            "z": 1,
            "elements": [
                "modularmachinery:blockcasing"
            ]
        },
        {
            "x": 4,
            "y": 1,
            "z": 2,
            "elements": [
                "nuclearcraft:solid_fission_sink@3"
            ]
        },
        {
            "x": 4,
            "y": -1,
            "z": 1,
            "elements": [
                "modularmachinery:blockcasing"
            ]
        },
        {
            "x": 5,
            "y": 1,
            "z": 2,
            "elements": [
                "modularmachinery:blockcasing"
            ]
        },
        {
            "x": -4,
            "y": 2,
            "z": 2,
            "elements": [
                "modularmachinery:blockcasing"
            ]
        },
        {
            "x": -4,
            "y": 0,
            "z": 1,
            "elements": [
                "modularmachinery:blockcasing"
            ]
        },
        {
            "x": -3,
            "y": 2,
            "z": 2,
            "elements": [
                "modularmachinery:blockcasing"
            ]
        },
        {
            "x": -3,
            "y": 0,
            "z": 1,
            "elements": [
                "modularmachinery:blockfluidinputhatch"
            ]
        },
        {
            "x": -2,
            "y": 2,
            "z": 2,
            "elements": [
                "thermalfoundation:storage_alloy@2"
            ]
        },
        {
            "x": -2,
            "y": 0,
            "z": 1,
            "elements": [
                "thermalfoundation:storage_alloy@2"
            ]
        },
        {
            "x": -1,
            "y": 2,
            "z": 2,
            "elements": [
                "nuclearcraft:solid_fission_sink@3"
            ]
        },
        {
            "x": -1,
            "y": 0,
            "z": 1,
            "elements": [
                "nuclearcraft:solid_fission_sink@7"
            ]
        },
        {
            "x": 0,
            "y": 2,
            "z": 2,
            "elements": [
                "nuclearcraft:solid_fission_sink@7"
            ]
        },
        {
            "x": 0,
            "y": 0,
            "z": 1,
            "elements": [
                "refraction:electric_laser@3"
            ]
        },
        {
            "x": 1,
            "y": 2,
            "z": 2,
            "elements": [
                "nuclearcraft:solid_fission_sink@3"
            ]
        },
        {
            "x": 1,
            "y": 0,
            "z": 1,
            "elements": [
                "nuclearcraft:solid_fission_sink@7"
            ]
        },
        {
            "x": 2,
            "y": 2,
            "z": 2,
            "elements": [
                "thermalfoundation:storage_alloy@2"
            ]
        },
        {
            "x": 2,
            "y": 0,
            "z": 1,
            "elements": [
                "thermalfoundation:storage_alloy@2"
            ]
        },
        {
            "x": 3,
            "y": 2,
            "z": 2,
            "elements": [
                "modularmachinery:blockcasing"
            ]
        },
        {
            "x": 3,
            "y": 0,
            "z": 1,
            "elements": [
                "modularmachinery:blockinputbus"
            ]
        },
        {
            "x": 4,
            "y": 2,
            "z": 2,
            "elements": [
                "modularmachinery:blockcasing"
            ]
        },
        {
            "x": 4,
            "y": 0,
            "z": 1,
            "elements": [
                "modularmachinery:blockcasing"
            ]
        },
        {
            "x": -4,
            "y": 1,
            "z": 1,
            "elements": [
                "modularmachinery:blockcasing"
            ]
        },
        {
            "x": -3,
            "y": 1,
            "z": 1,
            "elements": [
                "modularmachinery:blockcasing"
            ]
        },
        {
            "x": -2,
            "y": 1,
            "z": 1,
            "elements": [
                "thermalfoundation:storage_alloy@2"
            ]
        },
        {
            "x": -1,
            "y": 3,
            "z": 2,
            "elements": [
                "modularmachinery:blockcircuitry"
            ]
        },
        {
            "x": -1,
            "y": 1,
            "z": 1,
            "elements": [
                "nuclearcraft:solid_fission_sink@3"
            ]
        },
        {
            "x": 0,
            "y": 3,
            "z": 2,
            "elements": [
                "thermalfoundation:storage_alloy@2"
            ]
        },
        {
            "x": 0,
            "y": 1,
            "z": 1,
            "elements": [
                "nuclearcraft:solid_fission_sink@7"
            ]
        },
        {
            "x": 1,
            "y": 3,
            "z": 2,
            "elements": [
                "modularmachinery:blockcircuitry"
            ]
        },
        {
            "x": 1,
            "y": 1,
            "z": 1,
            "elements": [
                "nuclearcraft:solid_fission_sink@3"
            ]
        },
        {
            "x": 2,
            "y": 1,
            "z": 1,
            "elements": [
                "thermalfoundation:storage_alloy@2"
            ]
        },
        {
            "x": 3,
            "y": 1,
            "z": 1,
            "elements": [
                "modularmachinery:blockcasing"
            ]
        },
        {
            "x": 4,
            "y": 1,
            "z": 1,
            "elements": [
                "modularmachinery:blockcasing"
            ]
        },
        {
            "x": -1,
            "y": 2,
            "z": 1,
            "elements": [
                "modularmachinery:blockcircuitry"
            ]
        },
        {
            "x": 0,
            "y": 2,
            "z": 1,
            "elements": [
                "thermalfoundation:storage_alloy@2"
            ]
        }
    ]}